2024-01-08 12:40:21,258 - root - INFO - Building Model ...
2024-01-08 12:40:21,264 - root - INFO - Start Training ...
2024-01-08 12:40:21,540 - root - INFO - Start Training: Epoch 1
Traceback (most recent call last):
  File "/data/ephemeral/code/dkt/train.py", line 38, in <module>
    main(args)
  File "/data/ephemeral/code/dkt/train.py", line 32, in main
    trainer.run(args=args, train_data=train_data, valid_data=valid_data, model=model)
  File "/data/ephemeral/code/dkt/dkt/trainer.py", line 43, in run
    train_auc, train_acc, train_loss = train(train_loader=train_loader,
  File "/data/ephemeral/code/dkt/dkt/trainer.py", line 90, in train
    for step, batch in enumerate(train_loader):
  File "/opt/conda/envs/dkt/lib/python3.10/site-packages/torch/utils/data/dataloader.py", line 630, in __next__
    data = self._next_data()
  File "/opt/conda/envs/dkt/lib/python3.10/site-packages/torch/utils/data/dataloader.py", line 1345, in _next_data
    return self._process_data(data)
  File "/opt/conda/envs/dkt/lib/python3.10/site-packages/torch/utils/data/dataloader.py", line 1371, in _process_data
    data.reraise()
  File "/opt/conda/envs/dkt/lib/python3.10/site-packages/torch/_utils.py", line 694, in reraise
    raise exception
numpy.exceptions.AxisError: Caught AxisError in DataLoader worker process 0.
Original Traceback (most recent call last):
  File "/opt/conda/envs/dkt/lib/python3.10/site-packages/torch/utils/data/_utils/worker.py", line 308, in _worker_loop
    data = fetcher.fetch(index)
  File "/opt/conda/envs/dkt/lib/python3.10/site-packages/torch/utils/data/_utils/fetch.py", line 51, in fetch
    data = [self.dataset[idx] for idx in possibly_batched_index]
  File "/opt/conda/envs/dkt/lib/python3.10/site-packages/torch/utils/data/_utils/fetch.py", line 51, in <listcomp>
    data = [self.dataset[idx] for idx in possibly_batched_index]
  File "/data/ephemeral/code/dkt/dkt/dataloader.py", line 162, in __getitem__
    test, question, tag, correct = row[0], row[1], np.concatenate(row[2:-1], axis=1), row[-1]
numpy.exceptions.AxisError: axis 1 is out of bounds for array of dimension 1