2024-01-08 12:17:21,861 - root - INFO - Building Model ...
2024-01-08 12:17:21,867 - root - INFO - Start Training ...
2024-01-08 12:17:22,147 - root - INFO - Start Training: Epoch 1
Traceback (most recent call last):
  File "/data/ephemeral/code/dkt/train.py", line 38, in <module>
    main(args)
  File "/data/ephemeral/code/dkt/train.py", line 32, in main
    trainer.run(args=args, train_data=train_data, valid_data=valid_data, model=model)
  File "/data/ephemeral/code/dkt/dkt/trainer.py", line 43, in run
    train_auc, train_acc, train_loss = train(train_loader=train_loader,
  File "/data/ephemeral/code/dkt/dkt/trainer.py", line 90, in train
    for step, batch in enumerate(train_loader):
  File "/opt/conda/envs/dkt/lib/python3.10/site-packages/torch/utils/data/dataloader.py", line 630, in __next__
    data = self._next_data()
  File "/opt/conda/envs/dkt/lib/python3.10/site-packages/torch/utils/data/dataloader.py", line 1345, in _next_data
    return self._process_data(data)
  File "/opt/conda/envs/dkt/lib/python3.10/site-packages/torch/utils/data/dataloader.py", line 1371, in _process_data
    data.reraise()
  File "/opt/conda/envs/dkt/lib/python3.10/site-packages/torch/_utils.py", line 694, in reraise
    raise exception
RuntimeError: Caught RuntimeError in DataLoader worker process 0.
Original Traceback (most recent call last):
  File "/opt/conda/envs/dkt/lib/python3.10/site-packages/torch/utils/data/_utils/worker.py", line 308, in _worker_loop
    data = fetcher.fetch(index)
  File "/opt/conda/envs/dkt/lib/python3.10/site-packages/torch/utils/data/_utils/fetch.py", line 54, in fetch
    return self.collate_fn(data)
  File "/opt/conda/envs/dkt/lib/python3.10/site-packages/torch/utils/data/_utils/collate.py", line 265, in default_collate
    return collate(batch, collate_fn_map=default_collate_fn_map)
  File "/opt/conda/envs/dkt/lib/python3.10/site-packages/torch/utils/data/_utils/collate.py", line 127, in collate
    return elem_type({key: collate([d[key] for d in batch], collate_fn_map=collate_fn_map) for key in elem})
  File "/opt/conda/envs/dkt/lib/python3.10/site-packages/torch/utils/data/_utils/collate.py", line 127, in <dictcomp>
    return elem_type({key: collate([d[key] for d in batch], collate_fn_map=collate_fn_map) for key in elem})
  File "/opt/conda/envs/dkt/lib/python3.10/site-packages/torch/utils/data/_utils/collate.py", line 119, in collate
    return collate_fn_map[elem_type](batch, collate_fn_map=collate_fn_map)
  File "/opt/conda/envs/dkt/lib/python3.10/site-packages/torch/utils/data/_utils/collate.py", line 162, in collate_tensor_fn
    return torch.stack(batch, 0, out=out)
RuntimeError: stack expects each tensor to be equal size, but got [20, 26] at entry 0 and [20, 562] at entry 1